<!DOCTYPE html>
<html lang="en">
<head>
  <meta charset="UTF-8">
  <meta name="viewport" content="width=device-width, initial-scale=1.0">
  <meta http-equiv="X-UA-Compatible" content="ie=edge">
  <title>Document</title>
  <link rel="stylesheet" href="font.css">
</head>
<body>
    Promise.prototype.catch()
</body>
<script>
  // Promise.prototype.catch()

  // Promise.prototype.catch方法是.then(null, rejection)  或者  .then(undefined, rejection)的别名，用于指定发生错误时的回调函数
  /*
  
    getJSON('/posts.json').then(function(posts) {
      // ...
    }).catch(function(error) {
      // 处理 getJSON 和 前一个回调函数运行时发生的错误
      console.log('发生错误！', error);
    });
    
    上面代码中，getJSON方法返回一个 Promise 对象，如果该对象状态变为resolved，则会调用then方法指定的回调函数；
    如果异步操作抛出错误，状态就会变为rejected，就会调用catch方法指定的回调函数，处理这个错误。
    另外，then方法指定的回调函数，如果运行中抛出错误，也会被catch方法捕获

  */

  /*
    (1).
    p.then((val) => console.log('fulfilled:', val))
    .catch((err) => console.log('rejected', err));

    // 等同于
    p.then((val) => console.log('fulfilled:', val))
    .then(null, (err) => console.log("rejected:", err));

    (2).
    const promise = new Promise(function(resolve, reject) {
      throw new Error('test');
    });
    promise.catch(function(error) {
      console.log(error);
    });
    // Error: test

    上面两种写法等价于如下两种写法 >>>===

    // 写法一
    const promise = new Promise((resolve, reject) => {
      try {
        throw new Error('test');
      } catch(e) {
        reject(e)
      }
    })
    promise.catch((error) => {
      console.log(error)
    })

    // 写法二
    const promise = new Promise((resolve, reject) => {
      reject(throw new Error('test'))
    })
    promise.catch((error) => {
      console.log(error)
    })

    !!!!!!  比较上面两种写法，可以发现reject方法的作用，等同于抛出错误。
  */

  // (2).如果 Promise 状态已经变成resolved，再抛出错误是无效的
  let promise1 = new Promise((resolve, reject) => {
    resolve('ok')
    throw new Error('resolveError')
  })

  promise1.then(
    (value) => {
      console.log(value)
    }
  ).catch(
    (error) => {
      // 因为已经resolve了，所以catch不到上面的throw error 因为 Promise 的状态一旦改变，就永久保持该状态，不会再变了
      console.log(error)
    }
  )


  // (3).Promise 对象的错误具有“冒泡”性质，会一直向后传递，直到被捕获为止。也就是说，错误总是会被下一个catch语句捕获
  /*
  
    getJSON('/post/1.json').then(function(post) {
      return getJSON(post.commentURL);
    }).then(function(comments) {
      // some code
    }).catch(function(error) {
      // 处理前面三个Promise(一个由getJSON产生，两个由then产生)产生的错误
    });

  */


  // (4).一般来说，不要在then方法里面定义 Reject 状态的回调函数（即then的第二个参数），总是使用catch方法
  /*
  
    // bad
    promise.then((data) => {
      // success
    }, (error) => {
      // error
    })

    // good good good
    promise.then(() => {
      // success
    }).catch((error) => {
      // error
    })
  
  */


  // (5).跟传统的try/catch代码块不同的是，如果没有使用catch方法指定错误处理的回调函数，Promise 对象抛出的错误不会传递到外层代码，即不会有任何反应。
  const someAsyncThing = function() {
    return new Promise((resolve, reject) => {
      // 下面这句将会报错    因为 x 未定义
      return x + 2
    })
  }
  someAsyncThing().then(() => {
    console.log('everything is great！')
  })
  setTimeout(() => {
    console.log('继续执行，不会受promise错误的影响而终止！')
  },1500)
  // Promise 内部的错误不会影响到 Promise 外部的代码，通俗的说法就是“Promise 会吃掉错误”


  // (6). 
  const promise2 = new Promise(function (resolve, reject) {
    resolve('ok');
    setTimeout(function () { throw new Error('test') }, 0)
  });
  promise2.then(function (value) { console.log(value) });
  // ok
  // Uncaught Error: test
  // 上面代码中，Promise 指定在下一轮“事件循环”再抛出错误。
  // 到了那个时候，Promise 的运行已经结束了，所以这个错误是在 Promise 函数体外抛出的，会冒泡到最外层，成了未捕获的错误。
</script>
</html>